<?xml version="1.0" ?>
<sdf version="1.4">
  <model name="create">
    <link name="base">
      <inertial>
        <pose>0.001453 -0.000453 0.029787 0 0 0</pose>
        <inertia>
          <ixx>0.058640</ixx>
          <ixy>0.000124</ixy>
          <ixz>0.000615</ixz>
          <iyy>0.058786</iyy>
          <iyz>0.000014</iyz>
          <izz>1.532440</izz>
        </inertia>
        <mass>2.234000</mass>
      </inertial>

<!--
      <collision name="base_collision">
        <pose>0 0 0.047800 0 0 0</pose>
        <geometry>
          <cylinder>
            <radius>0.016495</radius>
            <length>0.061163</length>
          </cylinder>
        </geometry>
      </collision>
-->
      <visual name="base_visual">
        <pose>0 0 0.047800 0 0 0</pose>
        <geometry>
          <mesh>
            <uri>model://create/meshes/create_body.dae</uri>
          </mesh>
        </geometry>
      </visual>

      <collision name="front_wheel_collision">
        <pose>0.130000 0 0.017000 0 1.570700 1.570700</pose>
        <geometry>
          <sphere>
            <radius>0.018000</radius>
          </sphere>
        </geometry>
        <surface>
          <friction>
            <ode>
              <mu>0</mu>
              <mu2>0</mu2>
              <fdir1>0 0 0</fdir1>
              <slip1>0</slip1>
              <slip2>0</slip2>
            </ode>
          </friction>
        </surface>
      </collision>
      <visual name="front_wheel_visual">
        <pose>0.130000 0 0.017000 0 1.570700 1.570700</pose>
        <geometry>
          <sphere>
            <radius>0.009000</radius>
          </sphere>
        </geometry>
      </visual>

      <collision name="rear_wheel_collision">
        <pose>-0.13 0 0.017 0 1.5707 1.5707</pose>
        <geometry>
          <sphere>
            <radius>0.015000</radius>
          </sphere>
        </geometry>
        <surface>
          <friction>
            <ode>
              <mu>0</mu>
              <mu2>0</mu2>
              <fdir1>0 0 0</fdir1>
              <slip1>0</slip1>
              <slip2>0</slip2>
            </ode>
          </friction>
        </surface>
      </collision>
      <visual name="rear_wheel_visual">
        <pose>-0.130000 0 0.017000 0 1.570700 1.570700</pose>
        <geometry>
          <sphere>
            <radius>0.007500</radius>
          </sphere>
        </geometry>
      </visual>

<!-- Sensors -->
		<!-- 15x1 cameras act as 15 colour sensors -->

<sensor name="colour_sensor_1" type="camera">
  <camera>
    <horizontal_fov>1.5707</horizontal_fov>
    <image>
      <width>30</width>
      <height>1</height>
    </image>
    <clip>
      <near>0.1</near>
      <!-- Sensor range -->
      <far>4</far>
    </clip>
  </camera>
 <pose> .15 0 .05 0 0 0.785</pose>
  <plugin name="camera_controller" filename="libgazebo_ros_camera.so">
    <alwaysOn>true</alwaysOn>
    <cameraName>front_colour_sensor_1</cameraName>
    <imageTopicName>image_raw</imageTopicName>
    <cameraInfoTopicName>camera_info</cameraInfoTopicName>
    <frameName>camera_link</frameName>
    <hackBaseline>0.07</hackBaseline>
    <distortionK1>0.0</distortionK1>
    <distortionK2>0.0</distortionK2>
    <distortionK3>0.0</distortionK3>
    <distortionT1>0.0</distortionT1>
    <distortionT2>0.0</distortionT2>
  </plugin>
  <always_on>1</always_on>
  <update_rate>10</update_rate>
 <visualize>false</visualize>
</sensor>

<sensor name="colour_sensor_2" type="camera">
  <camera>
    <horizontal_fov>1.5707</horizontal_fov>
    <image>
      <width>30</width>
      <height>1</height>
    </image>
    <clip>
      <near>0.1</near>
      <!-- Sensor range -->
      <far>4</far>
    </clip>
  </camera>
 <pose> .15 0 .05 0 0 -0.785</pose>
  <plugin name="camera_controller" filename="libgazebo_ros_camera.so">
    <alwaysOn>true</alwaysOn>
    <cameraName>front_colour_sensor_2</cameraName>
    <imageTopicName>image_raw</imageTopicName>
    <cameraInfoTopicName>camera_info</cameraInfoTopicName>
    <frameName>camera_link</frameName>
    <hackBaseline>0.07</hackBaseline>
    <distortionK1>0.0</distortionK1>
    <distortionK2>0.0</distortionK2>
    <distortionK3>0.0</distortionK3>
    <distortionT1>0.0</distortionT1>
    <distortionT2>0.0</distortionT2>
  </plugin>
  <always_on>1</always_on>
  <update_rate>10</update_rate>
 <visualize>false</visualize>
</sensor>
    </link>


    <link name="left_wheel">
      <pose>0 0.130000 0.032000 0 0 0</pose>
      <inertial>
        <inertia>
          <ixx>0.001000</ixx>
          <ixy>0</ixy>
          <ixz>0</ixz>
          <iyy>0.001000</iyy>
          <iyz>0</iyz>
          <izz>0.001000</izz>
        </inertia>
        <mass>0.010000</mass>
      </inertial>
      <collision name="collision">
        <pose>0 0 0 0 1.570700 1.570700</pose>
        <geometry>
          <cylinder>
            <radius>0.033000</radius>
            <length>0.023000</length>
          </cylinder>
        </geometry>
        <surface>
          <friction>
            <ode>
              <mu>10</mu>
              <mu2>10</mu2>
              <fdir1>0 0 0</fdir1>
              <slip1>0</slip1>
              <slip2>0</slip2>
            </ode>
          </friction>
        </surface>
      </collision>
      <visual name="visual">
        <pose>0 0 0 0 1.570700 1.570700</pose>
        <geometry>
          <cylinder>
            <radius>0.033000</radius>
            <length>0.023000</length>
          </cylinder>
        </geometry>
      </visual>
    </link>

    <link name="right_wheel">
      <pose>0 -0.130000 0.032000 0 0 0</pose>
      <inertial>
        <inertia>
          <ixx>0.001000</ixx>
          <ixy>0</ixy>
          <ixz>0</ixz>
          <iyy>0.001000</iyy>
          <iyz>0</iyz>
          <izz>0.001000</izz>
        </inertia>
        <mass>0.010000</mass>
      </inertial>
      <collision name="collision">
        <pose>0 0 0 0 1.570700 1.570700</pose>
        <geometry>
          <cylinder>
            <radius>0.033000</radius>
            <length>0.023000</length>
          </cylinder>
        </geometry>
        <surface>
          <friction>
            <ode>
              <mu>10</mu>
              <mu2>10</mu2>
              <fdir1>0 0 0</fdir1>
              <slip1>0</slip1>
              <slip2>0</slip2>
            </ode>
          </friction>
        </surface>
      </collision>
      <visual name="visual">
        <pose>0 0 0 0 1.570700 1.570700</pose>
        <geometry>
          <cylinder>
            <radius>0.033000</radius>
            <length>0.023000</length>
          </cylinder>
        </geometry>
      </visual>
    </link>

    <joint name="left_wheel" type="revolute">
      <parent>base</parent>
      <child>left_wheel</child>
      <axis>
        <xyz>0 1 0</xyz>
      </axis>
    </joint>

    <joint name="right_wheel" type="revolute">
      <parent>base</parent>
      <child>right_wheel</child>
      <axis>
        <xyz>0 1 0</xyz>
      </axis>
    </joint>

    <plugin name="differential_drive_controller" filename="libgazebo_ros_diff_drive.so">
      <alwaysOn>true</alwaysOn>
      <updateRate>10</updateRate>
      <leftJoint>left_wheel</leftJoint>
      <rightJoint>right_wheel</rightJoint>
      <wheelSeparation>0.5380</wheelSeparation>
      <wheelDiameter>0.2410</wheelDiameter>
      <torque>20</torque>
      <commandTopic>cmd_vel</commandTopic>
      <odometryTopic>odom</odometryTopic>
      <odometryFrame>odom</odometryFrame>
      <robotBaseFrame>base_footprint</robotBaseFrame>
    </plugin>

		<plugin name="p3d_base_controller" filename="libgazebo_ros_p3d.so">
		  <alwaysOn>true</alwaysOn>
		  <updateRate>10</updateRate>
		  <bodyName>base</bodyName>
		  <topicName>base_pose</topicName>
		  <gaussianNoise>0</gaussianNoise>
		  <frameName>map</frameName>
		  <xyzOffsets>0 0 0</xyzOffsets> 
		  <rpyOffsets>0 0 0</rpyOffsets>
		  <interface:position name="p3d_base_position"/>
		</plugin>
      
  </model>
 
</sdf>
